2022-12-11 10:20:47,411] [INFO] file=E:\AutoGIS\pywps_flask_env\pywps-flask\pywps\app\Service.py line=310 module=Service function=call Request: describeprocess
2022-12-11 10:28:16,467] [INFO] file=E:\AutoGIS\pywps_flask_env\pywps-flask\pywps\app\Service.py line=310 module=Service function=call Request: describeprocess
2022-12-11 10:29:25,541] [INFO] file=E:\AutoGIS\pywps_flask_env\pywps-flask\pywps\app\Service.py line=310 module=Service function=call Request: describeprocess
2022-12-11 16:58:01,691] [INFO] file=E:\AutoGIS\pywps_flask_env\pywps-flask\pywps\app\Service.py line=310 module=Service function=call Request: getcapabilities
2022-12-11 16:58:05,471] [INFO] file=E:\AutoGIS\pywps_flask_env\pywps-flask\pywps\app\Service.py line=310 module=Service function=call Request: getcapabilities
2022-12-11 16:58:20,992] [INFO] file=E:\AutoGIS\pywps_flask_env\pywps-flask\pywps\app\Service.py line=310 module=Service function=call Request: getcapabilities
2022-12-11 16:58:23,571] [INFO] file=E:\AutoGIS\pywps_flask_env\pywps-flask\pywps\app\Service.py line=310 module=Service function=call Request: describeprocess
2022-12-11 16:58:33,162] [INFO] file=E:\AutoGIS\pywps_flask_env\pywps-flask\pywps\app\Service.py line=310 module=Service function=call Request: getcapabilities
2022-12-11 16:58:35,831] [INFO] file=E:\AutoGIS\pywps_flask_env\pywps-flask\pywps\app\Service.py line=310 module=Service function=call Request: execute
2022-12-11 16:58:36,297] [INFO] file=E:\AutoGIS\pywps_flask_env\pywps-flask\pywps\processing\__init__.py line=29 module=__init__ function=Process Processing mode: docker
2022-12-11 16:58:36,491] [ERROR] file=E:\AutoGIS\pywps_flask_env\pywps-flask\pywps\exceptions.py line=45 module=exceptions function=__init__ Exception: code: 500, description: No applicable error code, please check error log., locator: 
Traceback (most recent call last):
  File "E:\AutoGIS\pywps_flask_env\pywps-flask\pywps\app\Service.py", line 336, in call
    raise e
  File "E:\AutoGIS\pywps_flask_env\pywps-flask\pywps\app\Service.py", line 326, in call
    response = self.execute(
  File "E:\AutoGIS\pywps_flask_env\pywps-flask\pywps\app\Service.py", line 81, in execute
    return self._parse_and_execute(process, wps_request, uuid)
  File "E:\AutoGIS\pywps_flask_env\pywps-flask\pywps\app\Service.py", line 169, in _parse_and_execute
    wps_response = process.execute(wps_request, uuid)
  File "E:\AutoGIS\pywps_flask_env\pywps-flask\pywps\app\Process.py", line 148, in execute
    wps_response = self._execute_process(self.async_, wps_request, wps_response)
  File "E:\AutoGIS\pywps_flask_env\pywps-flask\pywps\app\Process.py", line 200, in _execute_process
    self._run_async(wps_request, wps_response)
  File "E:\AutoGIS\pywps_flask_env\pywps-flask\pywps\app\Process.py", line 229, in _run_async
    process.start()
  File "E:\AutoGIS\pywps_flask_env\pywps-flask\pywps\processing\basic.py", line 36, in start
    process.start()
  File "E:\Miniconda3\lib\multiprocessing\process.py", line 121, in start
    self._popen = self._Popen(self)
  File "E:\Miniconda3\lib\multiprocessing\context.py", line 224, in _Popen
    return _default_context.get_context().Process._Popen(process_obj)
  File "E:\Miniconda3\lib\multiprocessing\context.py", line 327, in _Popen
    return Popen(process_obj)
  File "E:\Miniconda3\lib\multiprocessing\popen_spawn_win32.py", line 93, in __init__
    reduction.dump(process_obj, to_child)
  File "E:\Miniconda3\lib\multiprocessing\reduction.py", line 60, in dump
    ForkingPickler(file, protocol).dump(obj)
TypeError: cannot pickle '_io.BufferedReader' object
2022-12-11 16:58:47,601] [INFO] file=E:\AutoGIS\pywps_flask_env\pywps-flask\pywps\app\Service.py line=310 module=Service function=call Request: getcapabilities
2022-12-11 16:58:50,352] [INFO] file=E:\AutoGIS\pywps_flask_env\pywps-flask\pywps\app\Service.py line=310 module=Service function=call Request: describeprocess
2022-12-11 16:59:01,542] [INFO] file=E:\AutoGIS\pywps_flask_env\pywps-flask\pywps\app\Service.py line=310 module=Service function=call Request: getcapabilities
2022-12-11 16:59:02,656] [INFO] file=E:\AutoGIS\pywps_flask_env\pywps-flask\pywps\app\Service.py line=310 module=Service function=call Request: getcapabilities
2022-12-11 16:59:04,051] [INFO] file=E:\AutoGIS\pywps_flask_env\pywps-flask\pywps\app\Service.py line=310 module=Service function=call Request: describeprocess
2022-12-11 16:59:05,232] [INFO] file=E:\AutoGIS\pywps_flask_env\pywps-flask\pywps\app\Service.py line=310 module=Service function=call Request: describeprocess
2022-12-11 16:59:07,212] [INFO] file=E:\AutoGIS\pywps_flask_env\pywps-flask\pywps\app\Service.py line=310 module=Service function=call Request: getcapabilities
2022-12-11 16:59:09,792] [INFO] file=E:\AutoGIS\pywps_flask_env\pywps-flask\pywps\app\Service.py line=310 module=Service function=call Request: getcapabilities
2022-12-11 17:00:11,395] [INFO] file=E:\AutoGIS\pywps_flask_env\pywps-flask\pywps\app\Service.py line=310 module=Service function=call Request: getcapabilities
2022-12-11 17:00:13,935] [INFO] file=E:\AutoGIS\pywps_flask_env\pywps-flask\pywps\app\Service.py line=310 module=Service function=call Request: describeprocess
2022-12-11 17:00:26,085] [INFO] file=E:\AutoGIS\pywps_flask_env\pywps-flask\pywps\app\Service.py line=310 module=Service function=call Request: getcapabilities
2022-12-11 17:00:28,665] [INFO] file=E:\AutoGIS\pywps_flask_env\pywps-flask\pywps\app\Service.py line=310 module=Service function=call Request: execute
2022-12-11 17:00:29,065] [INFO] file=E:\AutoGIS\pywps_flask_env\pywps-flask\pywps\processing\__init__.py line=29 module=__init__ function=Process Processing mode: docker
2022-12-11 17:00:29,205] [ERROR] file=E:\AutoGIS\pywps_flask_env\pywps-flask\pywps\exceptions.py line=45 module=exceptions function=__init__ Exception: code: 500, description: No applicable error code, please check error log., locator: 
Traceback (most recent call last):
  File "E:\AutoGIS\pywps_flask_env\pywps-flask\pywps\app\Service.py", line 336, in call
    raise e
  File "E:\AutoGIS\pywps_flask_env\pywps-flask\pywps\app\Service.py", line 326, in call
    response = self.execute(
  File "E:\AutoGIS\pywps_flask_env\pywps-flask\pywps\app\Service.py", line 81, in execute
    return self._parse_and_execute(process, wps_request, uuid)
  File "E:\AutoGIS\pywps_flask_env\pywps-flask\pywps\app\Service.py", line 169, in _parse_and_execute
    wps_response = process.execute(wps_request, uuid)
  File "E:\AutoGIS\pywps_flask_env\pywps-flask\pywps\app\Process.py", line 148, in execute
    wps_response = self._execute_process(self.async_, wps_request, wps_response)
  File "E:\AutoGIS\pywps_flask_env\pywps-flask\pywps\app\Process.py", line 200, in _execute_process
    self._run_async(wps_request, wps_response)
  File "E:\AutoGIS\pywps_flask_env\pywps-flask\pywps\app\Process.py", line 229, in _run_async
    process.start()
  File "E:\AutoGIS\pywps_flask_env\pywps-flask\pywps\processing\basic.py", line 36, in start
    process.start()
  File "E:\Miniconda3\lib\multiprocessing\process.py", line 121, in start
    self._popen = self._Popen(self)
  File "E:\Miniconda3\lib\multiprocessing\context.py", line 224, in _Popen
    return _default_context.get_context().Process._Popen(process_obj)
  File "E:\Miniconda3\lib\multiprocessing\context.py", line 327, in _Popen
    return Popen(process_obj)
  File "E:\Miniconda3\lib\multiprocessing\popen_spawn_win32.py", line 93, in __init__
    reduction.dump(process_obj, to_child)
  File "E:\Miniconda3\lib\multiprocessing\reduction.py", line 60, in dump
    ForkingPickler(file, protocol).dump(obj)
TypeError: cannot pickle '_io.BufferedReader' object
2022-12-11 17:00:43,035] [INFO] file=E:\AutoGIS\pywps_flask_env\pywps-flask\pywps\app\Service.py line=310 module=Service function=call Request: getcapabilities
2022-12-11 17:00:45,615] [INFO] file=E:\AutoGIS\pywps_flask_env\pywps-flask\pywps\app\Service.py line=310 module=Service function=call Request: getcapabilities
2022-12-11 17:00:58,840] [INFO] file=E:\AutoGIS\pywps_flask_env\pywps-flask\pywps\app\Service.py line=310 module=Service function=call Request: getcapabilities
2022-12-11 17:01:01,385] [INFO] file=E:\AutoGIS\pywps_flask_env\pywps-flask\pywps\app\Service.py line=310 module=Service function=call Request: describeprocess
2022-12-11 17:01:59,915] [INFO] file=E:\AutoGIS\pywps_flask_env\pywps-flask\pywps\app\Service.py line=310 module=Service function=call Request: describeprocess
2022-12-11 17:02:03,880] [INFO] file=E:\AutoGIS\pywps_flask_env\pywps-flask\pywps\app\Service.py line=310 module=Service function=call Request: describeprocess
2022-12-11 17:03:36,948] [INFO] file=E:\AutoGIS\pywps_flask_env\pywps-flask\pywps\app\Service.py line=310 module=Service function=call Request: getcapabilities
2022-12-11 17:03:39,568] [INFO] file=E:\AutoGIS\pywps_flask_env\pywps-flask\pywps\app\Service.py line=310 module=Service function=call Request: describeprocess
2022-12-11 17:03:45,718] [INFO] file=E:\AutoGIS\pywps_flask_env\pywps-flask\pywps\app\Service.py line=310 module=Service function=call Request: getcapabilities
2022-12-11 17:03:48,368] [INFO] file=E:\AutoGIS\pywps_flask_env\pywps-flask\pywps\app\Service.py line=310 module=Service function=call Request: execute
2022-12-11 17:03:48,528] [INFO] file=E:\AutoGIS\pywps_flask_env\pywps-flask\pywps\validator\complexvalidator.py line=40 module=complexvalidator function=validategml validating GML; Mode: 0
2022-12-11 17:03:48,758] [INFO] file=E:\AutoGIS\pywps_flask_env\pywps-flask\pywps\processing\__init__.py line=29 module=__init__ function=Process Processing mode: docker
2022-12-11 17:03:48,912] [ERROR] file=E:\AutoGIS\pywps_flask_env\pywps-flask\pywps\exceptions.py line=45 module=exceptions function=__init__ Exception: code: 500, description: No applicable error code, please check error log., locator: 
Traceback (most recent call last):
  File "E:\AutoGIS\pywps_flask_env\pywps-flask\pywps\app\Service.py", line 336, in call
    raise e
  File "E:\AutoGIS\pywps_flask_env\pywps-flask\pywps\app\Service.py", line 326, in call
    response = self.execute(
  File "E:\AutoGIS\pywps_flask_env\pywps-flask\pywps\app\Service.py", line 81, in execute
    return self._parse_and_execute(process, wps_request, uuid)
  File "E:\AutoGIS\pywps_flask_env\pywps-flask\pywps\app\Service.py", line 169, in _parse_and_execute
    wps_response = process.execute(wps_request, uuid)
  File "E:\AutoGIS\pywps_flask_env\pywps-flask\pywps\app\Process.py", line 148, in execute
    wps_response = self._execute_process(self.async_, wps_request, wps_response)
  File "E:\AutoGIS\pywps_flask_env\pywps-flask\pywps\app\Process.py", line 200, in _execute_process
    self._run_async(wps_request, wps_response)
  File "E:\AutoGIS\pywps_flask_env\pywps-flask\pywps\app\Process.py", line 229, in _run_async
    process.start()
  File "E:\AutoGIS\pywps_flask_env\pywps-flask\pywps\processing\basic.py", line 36, in start
    process.start()
  File "E:\Miniconda3\lib\multiprocessing\process.py", line 121, in start
    self._popen = self._Popen(self)
  File "E:\Miniconda3\lib\multiprocessing\context.py", line 224, in _Popen
    return _default_context.get_context().Process._Popen(process_obj)
  File "E:\Miniconda3\lib\multiprocessing\context.py", line 327, in _Popen
    return Popen(process_obj)
  File "E:\Miniconda3\lib\multiprocessing\popen_spawn_win32.py", line 93, in __init__
    reduction.dump(process_obj, to_child)
  File "E:\Miniconda3\lib\multiprocessing\reduction.py", line 60, in dump
    ForkingPickler(file, protocol).dump(obj)
TypeError: cannot pickle '_io.BufferedReader' object
2022-12-11 17:17:11,513] [INFO] file=E:\AutoGIS\pywps_flask_env\pywps-flask\pywps\app\Service.py line=310 module=Service function=call Request: getcapabilities
2022-12-11 17:17:14,354] [INFO] file=E:\AutoGIS\pywps_flask_env\pywps-flask\pywps\app\Service.py line=310 module=Service function=call Request: describeprocess
2022-12-11 17:17:21,893] [INFO] file=E:\AutoGIS\pywps_flask_env\pywps-flask\pywps\app\Service.py line=310 module=Service function=call Request: getcapabilities
2022-12-11 17:17:24,513] [INFO] file=E:\AutoGIS\pywps_flask_env\pywps-flask\pywps\app\Service.py line=310 module=Service function=call Request: execute
2022-12-11 17:17:24,953] [INFO] file=E:\AutoGIS\pywps_flask_env\pywps-flask\pywps\processing\__init__.py line=29 module=__init__ function=Process Processing mode: docker
2022-12-11 17:17:25,103] [ERROR] file=E:\AutoGIS\pywps_flask_env\pywps-flask\pywps\exceptions.py line=45 module=exceptions function=__init__ Exception: code: 500, description: No applicable error code, please check error log., locator: 
Traceback (most recent call last):
  File "E:\AutoGIS\pywps_flask_env\pywps-flask\pywps\app\Service.py", line 336, in call
    raise e
  File "E:\AutoGIS\pywps_flask_env\pywps-flask\pywps\app\Service.py", line 326, in call
    response = self.execute(
  File "E:\AutoGIS\pywps_flask_env\pywps-flask\pywps\app\Service.py", line 81, in execute
    return self._parse_and_execute(process, wps_request, uuid)
  File "E:\AutoGIS\pywps_flask_env\pywps-flask\pywps\app\Service.py", line 169, in _parse_and_execute
    wps_response = process.execute(wps_request, uuid)
  File "E:\AutoGIS\pywps_flask_env\pywps-flask\pywps\app\Process.py", line 148, in execute
    wps_response = self._execute_process(self.async_, wps_request, wps_response)
  File "E:\AutoGIS\pywps_flask_env\pywps-flask\pywps\app\Process.py", line 200, in _execute_process
    self._run_async(wps_request, wps_response)
  File "E:\AutoGIS\pywps_flask_env\pywps-flask\pywps\app\Process.py", line 229, in _run_async
    process.start()
  File "E:\AutoGIS\pywps_flask_env\pywps-flask\pywps\processing\basic.py", line 36, in start
    process.start()
  File "E:\Miniconda3\lib\multiprocessing\process.py", line 121, in start
    self._popen = self._Popen(self)
  File "E:\Miniconda3\lib\multiprocessing\context.py", line 224, in _Popen
    return _default_context.get_context().Process._Popen(process_obj)
  File "E:\Miniconda3\lib\multiprocessing\context.py", line 327, in _Popen
    return Popen(process_obj)
  File "E:\Miniconda3\lib\multiprocessing\popen_spawn_win32.py", line 93, in __init__
    reduction.dump(process_obj, to_child)
  File "E:\Miniconda3\lib\multiprocessing\reduction.py", line 60, in dump
    ForkingPickler(file, protocol).dump(obj)
TypeError: cannot pickle '_io.BufferedReader' object
2022-12-11 17:22:18,354] [INFO] file=E:\AutoGIS\pywps_flask_env\pywps-flask\pywps\app\Service.py line=310 module=Service function=call Request: describeprocess
2022-12-11 17:22:27,024] [INFO] file=E:\AutoGIS\pywps_flask_env\pywps-flask\pywps\app\Service.py line=310 module=Service function=call Request: describeprocess
2022-12-11 17:22:51,904] [INFO] file=E:\AutoGIS\pywps_flask_env\pywps-flask\pywps\app\Service.py line=310 module=Service function=call Request: getcapabilities
2022-12-11 17:22:54,504] [INFO] file=E:\AutoGIS\pywps_flask_env\pywps-flask\pywps\app\Service.py line=310 module=Service function=call Request: getcapabilities
2022-12-11 17:22:58,134] [INFO] file=E:\AutoGIS\pywps_flask_env\pywps-flask\pywps\app\Service.py line=310 module=Service function=call Request: getcapabilities
2022-12-11 17:23:00,755] [INFO] file=E:\AutoGIS\pywps_flask_env\pywps-flask\pywps\app\Service.py line=310 module=Service function=call Request: describeprocess
2022-12-11 17:23:07,236] [INFO] file=E:\AutoGIS\pywps_flask_env\pywps-flask\pywps\app\Service.py line=310 module=Service function=call Request: getcapabilities
2022-12-11 17:23:09,794] [INFO] file=E:\AutoGIS\pywps_flask_env\pywps-flask\pywps\app\Service.py line=310 module=Service function=call Request: execute
2022-12-11 17:25:47,311] [INFO] file=E:\AutoGIS\pywps_flask_env\pywps-flask\pywps\app\Service.py line=310 module=Service function=call Request: describeprocess
2022-12-11 17:28:50,897] [INFO] file=E:\AutoGIS\pywps_flask_env\pywps-flask\pywps\app\Service.py line=310 module=Service function=call Request: getcapabilities
2022-12-11 17:28:53,712] [INFO] file=E:\AutoGIS\pywps_flask_env\pywps-flask\pywps\app\Service.py line=310 module=Service function=call Request: getcapabilities
2022-12-11 17:28:57,202] [INFO] file=E:\AutoGIS\pywps_flask_env\pywps-flask\pywps\app\Service.py line=310 module=Service function=call Request: getcapabilities
2022-12-11 17:28:59,832] [INFO] file=E:\AutoGIS\pywps_flask_env\pywps-flask\pywps\app\Service.py line=310 module=Service function=call Request: describeprocess
2022-12-11 17:29:04,307] [INFO] file=E:\AutoGIS\pywps_flask_env\pywps-flask\pywps\app\Service.py line=310 module=Service function=call Request: getcapabilities
2022-12-11 17:29:06,932] [INFO] file=E:\AutoGIS\pywps_flask_env\pywps-flask\pywps\app\Service.py line=310 module=Service function=call Request: execute
2022-12-11 17:29:51,732] [INFO] file=E:\AutoGIS\pywps_flask_env\pywps-flask\pywps\app\Service.py line=310 module=Service function=call Request: getcapabilities
2022-12-11 17:29:54,601] [INFO] file=E:\AutoGIS\pywps_flask_env\pywps-flask\pywps\app\Service.py line=310 module=Service function=call Request: describeprocess
2022-12-11 17:30:01,312] [INFO] file=E:\AutoGIS\pywps_flask_env\pywps-flask\pywps\app\Service.py line=310 module=Service function=call Request: getcapabilities
2022-12-11 17:30:03,922] [INFO] file=E:\AutoGIS\pywps_flask_env\pywps-flask\pywps\app\Service.py line=310 module=Service function=call Request: execute
2022-12-11 17:30:04,277] [INFO] file=E:\AutoGIS\pywps_flask_env\pywps-flask\pywps\processing\__init__.py line=29 module=__init__ function=Process Processing mode: docker
2022-12-11 17:30:04,426] [ERROR] file=E:\AutoGIS\pywps_flask_env\pywps-flask\pywps\exceptions.py line=45 module=exceptions function=__init__ Exception: code: 500, description: No applicable error code, please check error log., locator: 
Traceback (most recent call last):
  File "E:\AutoGIS\pywps_flask_env\pywps-flask\pywps\app\Service.py", line 336, in call
    raise e
  File "E:\AutoGIS\pywps_flask_env\pywps-flask\pywps\app\Service.py", line 326, in call
    response = self.execute(
  File "E:\AutoGIS\pywps_flask_env\pywps-flask\pywps\app\Service.py", line 81, in execute
    return self._parse_and_execute(process, wps_request, uuid)
  File "E:\AutoGIS\pywps_flask_env\pywps-flask\pywps\app\Service.py", line 169, in _parse_and_execute
    wps_response = process.execute(wps_request, uuid)
  File "E:\AutoGIS\pywps_flask_env\pywps-flask\pywps\app\Process.py", line 148, in execute
    wps_response = self._execute_process(self.async_, wps_request, wps_response)
  File "E:\AutoGIS\pywps_flask_env\pywps-flask\pywps\app\Process.py", line 200, in _execute_process
    self._run_async(wps_request, wps_response)
  File "E:\AutoGIS\pywps_flask_env\pywps-flask\pywps\app\Process.py", line 229, in _run_async
    process.start()
  File "E:\AutoGIS\pywps_flask_env\pywps-flask\pywps\processing\basic.py", line 36, in start
    process.start()
  File "E:\Miniconda3\lib\multiprocessing\process.py", line 121, in start
    self._popen = self._Popen(self)
  File "E:\Miniconda3\lib\multiprocessing\context.py", line 224, in _Popen
    return _default_context.get_context().Process._Popen(process_obj)
  File "E:\Miniconda3\lib\multiprocessing\context.py", line 327, in _Popen
    return Popen(process_obj)
  File "E:\Miniconda3\lib\multiprocessing\popen_spawn_win32.py", line 93, in __init__
    reduction.dump(process_obj, to_child)
  File "E:\Miniconda3\lib\multiprocessing\reduction.py", line 60, in dump
    ForkingPickler(file, protocol).dump(obj)
TypeError: cannot pickle '_io.BufferedReader' object
2022-12-11 17:31:05,928] [INFO] file=E:\AutoGIS\pywps_flask_env\pywps-flask\pywps\app\Service.py line=310 module=Service function=call Request: getcapabilities
2022-12-11 17:31:08,729] [INFO] file=E:\AutoGIS\pywps_flask_env\pywps-flask\pywps\app\Service.py line=310 module=Service function=call Request: getcapabilities
2022-12-11 17:31:13,379] [INFO] file=E:\AutoGIS\pywps_flask_env\pywps-flask\pywps\app\Service.py line=310 module=Service function=call Request: getcapabilities
2022-12-11 17:31:15,911] [INFO] file=E:\AutoGIS\pywps_flask_env\pywps-flask\pywps\app\Service.py line=310 module=Service function=call Request: describeprocess
2022-12-11 17:31:21,439] [INFO] file=E:\AutoGIS\pywps_flask_env\pywps-flask\pywps\app\Service.py line=310 module=Service function=call Request: getcapabilities
2022-12-11 17:31:24,009] [INFO] file=E:\AutoGIS\pywps_flask_env\pywps-flask\pywps\app\Service.py line=310 module=Service function=call Request: execute
2022-12-11 17:31:24,429] [INFO] file=E:\AutoGIS\pywps_flask_env\pywps-flask\pywps\processing\__init__.py line=29 module=__init__ function=Process Processing mode: docker
2022-12-11 17:31:24,578] [ERROR] file=E:\AutoGIS\pywps_flask_env\pywps-flask\pywps\exceptions.py line=45 module=exceptions function=__init__ Exception: code: 500, description: No applicable error code, please check error log., locator: 
Traceback (most recent call last):
  File "E:\AutoGIS\pywps_flask_env\pywps-flask\pywps\app\Service.py", line 336, in call
    raise e
  File "E:\AutoGIS\pywps_flask_env\pywps-flask\pywps\app\Service.py", line 326, in call
    response = self.execute(
  File "E:\AutoGIS\pywps_flask_env\pywps-flask\pywps\app\Service.py", line 81, in execute
    return self._parse_and_execute(process, wps_request, uuid)
  File "E:\AutoGIS\pywps_flask_env\pywps-flask\pywps\app\Service.py", line 169, in _parse_and_execute
    wps_response = process.execute(wps_request, uuid)
  File "E:\AutoGIS\pywps_flask_env\pywps-flask\pywps\app\Process.py", line 148, in execute
    wps_response = self._execute_process(self.async_, wps_request, wps_response)
  File "E:\AutoGIS\pywps_flask_env\pywps-flask\pywps\app\Process.py", line 200, in _execute_process
    self._run_async(wps_request, wps_response)
  File "E:\AutoGIS\pywps_flask_env\pywps-flask\pywps\app\Process.py", line 229, in _run_async
    process.start()
  File "E:\AutoGIS\pywps_flask_env\pywps-flask\pywps\processing\basic.py", line 36, in start
    process.start()
  File "E:\Miniconda3\lib\multiprocessing\process.py", line 121, in start
    self._popen = self._Popen(self)
  File "E:\Miniconda3\lib\multiprocessing\context.py", line 224, in _Popen
    return _default_context.get_context().Process._Popen(process_obj)
  File "E:\Miniconda3\lib\multiprocessing\context.py", line 327, in _Popen
    return Popen(process_obj)
  File "E:\Miniconda3\lib\multiprocessing\popen_spawn_win32.py", line 93, in __init__
    reduction.dump(process_obj, to_child)
  File "E:\Miniconda3\lib\multiprocessing\reduction.py", line 60, in dump
    ForkingPickler(file, protocol).dump(obj)
TypeError: cannot pickle '_io.BufferedReader' object
2022-12-11 17:32:38,819] [INFO] file=E:\AutoGIS\pywps_flask_env\pywps-flask\pywps\app\Service.py line=310 module=Service function=call Request: getcapabilities
2022-12-11 17:32:41,899] [INFO] file=E:\AutoGIS\pywps_flask_env\pywps-flask\pywps\app\Service.py line=310 module=Service function=call Request: getcapabilities
2022-12-11 17:32:46,549] [INFO] file=E:\AutoGIS\pywps_flask_env\pywps-flask\pywps\app\Service.py line=310 module=Service function=call Request: getcapabilities
2022-12-11 17:32:49,128] [INFO] file=E:\AutoGIS\pywps_flask_env\pywps-flask\pywps\app\Service.py line=310 module=Service function=call Request: describeprocess
2022-12-11 17:32:54,009] [INFO] file=E:\AutoGIS\pywps_flask_env\pywps-flask\pywps\app\Service.py line=310 module=Service function=call Request: getcapabilities
2022-12-11 17:32:56,529] [INFO] file=E:\AutoGIS\pywps_flask_env\pywps-flask\pywps\app\Service.py line=310 module=Service function=call Request: execute
